Workbook

Sheet Dataset
A1: SOFTWARE PROJECT RISK DATASET — Pressman (2014, Ch.28) | COCOMO II (Boehm 2000) | NASA/PROMISE
A2: Contains ONLY measurable project attributes and the final ML target label. Probability, Impact, Risk Exposure and aggregation are calculated in 'Risk_Calculation_Engine' (not stored here). Full derivation rules are in 'Risk_Assessment_Rules'; full methodology narrative is in 'Risk_Label_Methodology'.
A4: Project_ID | B4: KSLOC | C4: CPLX | D4: Effort_PM | E4: Duration_Months | F4: Capability_Index | G4: Requirements_Change_Count | H4: Schedule_Pressure_Index | I4: Team_Size | J4: Defect_Count | K4: Defect_Density | L4: Defect_Resolution_Rate | M4: Defect_Trend | N4: Risk_Level | O4: Risk_Label
A5: 1 | B5: 78.4 | C5: 4 | D5: 297.1 | E5: =ROUND(3.67*D5^0.28/H5,2) -> 7.23 | F5: 3 | G5: 5 | H5: 2.5 | I5: 10 | J5: 974 | K5: 12.42 | L5: 77.1 | M5: 1 | N5: =IF(Risk_Calculation_Engine!U5="Low",1,IF(Risk_Calculation_Engine!U5="Medium",2,3)) -> 3 | O5: =Risk_Calculation_Engine!U5 -> High
A6: 2 | B6: 108.2 | C6: 2 | D6: 417.9 | E6: =ROUND(3.67*D6^0.28/H6,2) -> 7.95 | F6: 2 | G6: 5 | H6: 2.5 | I6: 6 | J6: 478 | K6: 4.42 | L6: 68.6 | M6: 1 | N6: =IF(Risk_Calculation_Engine!U6="Low",1,IF(Risk_Calculation_Engine!U6="Medium",2,3)) -> 2 | O6: =Risk_Calculation_Engine!U6 -> Medium
A7: 3 | B7: 68.3 | C7: 4 | D7: 256.2 | E7: =ROUND(3.67*D7^0.28/H7,2) -> 11.96 | F7: 3 | G7: 3 | H7: 1.45 | I7: 10 | J7: 742 | K7: 10.86 | L7: 90.5 | M7: 1 | N7: =IF(Risk_Calculation_Engine!U7="Low",1,IF(Risk_Calculation_Engine!U7="Medium",2,3)) -> 1 | O7: =Risk_Calculation_Engine!U7 -> Low
A8: 4 | B8: 60.7 | C8: 3 | D8: 179.6 | E8: =ROUND(3.67*D8^0.28/H8,2) -> 13.77 | F8: 3 | G8: 10 | H8: 1.14 | I8: 4 | J8: 316 | K8: 5.21 | L8: 88.4 | M8: 1 | N8: =IF(Risk_Calculation_Engine!U8="Low",1,IF(Risk_Calculation_Engine!U8="Medium",2,3)) -> 2 | O8: =Risk_Calculation_Engine!U8 -> Medium
A9: 5 | B9: 118 | C9: 3 | D9: 495.2 | E9: =ROUND(3.67*D9^0.28/H9,2) -> 21.95 | F9: 2 | G9: 2 | H9: 0.95 | I9: 9 | J9: 945 | K9: 8.01 | L9: 48.8 | M9: 3 | N9: =IF(Risk_Calculation_Engine!U9="Low",1,IF(Risk_Calculation_Engine!U9="Medium",2,3)) -> 1 | O9: =Risk_Calculation_Engine!U9 -> Low
A10: 6 | B10: 65 | C10: 2 | D10: 320.6 | E10: =ROUND(3.67*D10^0.28/H10,2) -> 21.98 | F10: 1 | G10: 2 | H10: 0.84 | I10: 10 | J10: 368 | K10: 5.66 | L10: 70.8 | M10: 1 | N10: =IF(Risk_Calculation_Engine!U10="Low",1,IF(Risk_Calculation_Engine!U10="Medium",2,3)) -> 1 | O10: =Risk_Calculation_Engine!U10 -> Low
A11: 7 | B11: 88.6 | C11: 3 | D11: 265.7 | E11: =ROUND(3.67*D11^0.28/H11,2) -> 14.48 | F11: 3 | G11: 11 | H11: 1.21 | I11: 10 | J11: 716 | K11: 8.08 | L11: 83.9 | M11: 1 | N11: =IF(Risk_Calculation_Engine!U11="Low",1,IF(Risk_Calculation_Engine!U11="Medium",2,3)) -> 2 | O11: =Risk_Calculation_Engine!U11 -> Medium
A12: 8 | B12: 82.3 | C12: 3 | D12: 516.3 | E12: =ROUND(3.67*D12^0.28/H12,2) -> 8.98 | F12: 1 | G12: 12 | H12: 2.35 | I12: 8 | J12: 677 | K12: 8.23 | L12: 79.1 | M12: 3 | N12: =IF(Risk_Calculation_Engine!U12="Low",1,IF(Risk_Calculation_Engine!U12="Medium",2,3)) -> 3 | O12: =Risk_Calculation_Engine!U12 -> High
A13: 9 | B13: 118 | C13: 3 | D13: 500.8 | E13: =ROUND(3.67*D13^0.28/H13,2) -> 8.64 | F13: 2 | G13: 5 | H13: 2.42 | I13: 11 | J13: 997 | K13: 8.45 | L13: 70.1 | M13: 3 | N13: =IF(Risk_Calculation_Engine!U13="Low",1,IF(Risk_Calculation_Engine!U13="Medium",2,3)) -> 2 | O13: =Risk_Calculation_Engine!U13 -> Medium
A14: 10 | B14: 52.7 | C14: 2 | D14: 174.4 | E14: =ROUND(3.67*D14^0.28/H14,2) -> 8.28 | F14: 2 | G14: 9 | H14: 1.88 | I14: 9 | J14: 148 | K14: 2.81 | L14: 59 | M14: 1 | N14: =IF(Risk_Calculation_Engine!U14="Low",1,IF(Risk_Calculation_Engine!U14="Medium",2,3)) -> 2 | O14: =Risk_Calculation_Engine!U14 -> Medium
A15: 11 | B15: 147.1 | C15: 2 | D15: 682.5 | E15: =ROUND(3.67*D15^0.28/H15,2) -> 16.07 | F15: 2 | G15: 11 | H15: 1.42 | I15: 6 | J15: 597 | K15: 4.06 | L15: 71.9 | M15: 1 | N15: =IF(Risk_Calculation_Engine!U15="Low",1,IF(Risk_Calculation_Engine!U15="Medium",2,3)) -> 3 | O15: =Risk_Calculation_Engine!U15 -> High
A16: 12 | B16: 42.3 | C16: 3 | D16: 254 | E16: =ROUND(3.67*D16^0.28/H16,2) -> 9.01 | F16: 1 | G16: 7 | H16: 1.92 | I16: 5 | J16: 263 | K16: 6.22 | L16: 44.3 | M16: 3 | N16: =IF(Risk_Calculation_Engine!U16="Low",1,IF(Risk_Calculation_Engine!U16="Medium",2,3)) -> 3 | O16: =Risk_Calculation_Engine!U16 -> High
... A1504: 1500 | B1504: 58 | C1504: 3 | D1504: 273.6 | E1504: =ROUND(3.67*D1504^0.28/H1504,2) -> 7.71 | F1504: 2 | G1504: 2 | H1504: 2.29 | I1504: 14 | J1504: 180 | K1504: 3.1 | L1504: 81 | M1504: 1 | N1504: =IF(Risk_Calculation_Engine!U1504="Low",1,IF(Risk_Calculation_Engine!U1504="Medium",2,3)) -> 1 | O1504: =Risk_Calculation_Engine!U1504 -> Low

Sheet Column_Dictionary
A1: COLUMN DICTIONARY — Software Project Risk Dataset (12 features + Project_ID + Risk_Level target)
A2: Every stored attribute is grounded in Pressman (2014) Chapter 28, COCOMO II (Boehm 2000), or NASA/PROMISE defect research. No intermediate risk-scoring columns (Probability, Impact, RE, category risk score) are stored here by design — see 'Risk_Calculation_Engine' for those calculations and 'Risk_Assessment_Rules' for their justification.
A4: # | B4: Feature | C4: Pressman Category | D4: Source | E4: Unit / Scale | F4: Definition | G4: Measurement Method | H4: Reason It Influences Software Project Risk
A5: 1 | B5: Project_ID | C5: — | D5: Auto-generated | E5: 1-1500 | F5: Unique sequential identifier for record tracing. | G5: Auto-incremented integer. | H5: No predictive value; excluded from ML features. Used only to trace a row back to a project.
A6: 2 | B6: KSLOC | C6: PS | D6: COCOMO II (Boehm 2000) | E6: Thousands of SLOC (non-comment, non-blank) | F6: Estimated software size in Kilo Source Lines of Code. | G6: Estimated at planning via analogy, function-point backfiring, or direct design-spec counting. Primary size driver in COCOMO II: PM=2.94xKSLOC^1.10xEAF. | H6: Pressman (2014, Ch.28) names Product Size the first risk category. Larger systems show non-linear growth in integration complexity, estimation error and defect probability (Brooks, 1995).
A7: 3 | B7: CPLX | C7: TE | D7: COCOMO II (Boehm 2000) | E7: Ordinal 1=VL 2=L 3=N 4=H 5=VH | F7: Product Complexity cost driver — a composite rating of control flow, computational, device-dependent, data-management and UI operations (NOT cyclomatic complexity). | G7: Rated using COCOMO II Table A.8 (Boehm 2000). EAF multipliers: VL=0.73 L=0.87 N=1.00 H=1.17 VH=1.34. | H7: Higher CPLX raises implementation difficulty and defect-injection rate, directly driving Pressman's Technology (TE) risk category.
A8: 4 | B8: Effort_PM | C8: PS | D8: COCOMO II (Boehm 2000) | E8: Person-Months (1 PM=152 hrs) | F8: Total estimated development effort computed via COCOMO II Early Design model: PM=2.94xKSLOC^1.10xEAF. | G8: Apply the COCOMO II formula with the CPLX and Capability EAF multipliers. | H8: Effort overrun is a direct consequence of poor process definition and undersized estimation (Pressman PS/PR risk); it also underlies the Duration and Schedule Pressure calculations.
A9: 5 | B9: Duration_Months | C9: PR | D9: COCOMO II (Boehm 2000), derived | E9: Months | F9: Actual calendar time allocated to the project. Consistent with COCOMO II required duration TDEV=3.67xPM^0.28 and the recorded Schedule Pressure Index (SPI=TDEV/Duration). | G9: Computed in-sheet as Duration_Months = TDEV / Schedule_Pressure_Index, so it is always internally consistent with Effort and SPI. | H9: A short duration relative to COCOMO II's TDEV estimate is the raw driver of schedule compression — Pressman's "arbitrary completion date" process risk indicator.
A10: 6 | B10: Capability_Index | C10: ST | D10: COCOMO II (Boehm 2000) | E10: Ordinal 1=Low 2=Medium 3=High | F10: Composite of COCOMO II ACAP (Analyst Capability) and PCAP (Programmer Capability) cost drivers. | G10: Rated via COCOMO II capability tables. Low=15th percentile (EAF 1.369), Medium=55th percentile (EAF 1.00), High=75th percentile (EAF 0.748). | H10: Pressman's Staff (ST) risk rises as capability falls: lower-capability teams show higher defect injection and rework rates (Brooks, 1995).
A11: 7 | B11: Requirements_Change_Count | C11: CU | D11: Pressman (2014) Ch.28 | E11: Count (integer, 0-20) | F11: Total approved requirement change requests (CRs) during the project. | G11: Count formal CRs logged in a change-control system (e.g. Jira CR tickets, CCB approvals); informal requests excluded. | H11: Pressman lists requirement-change likelihood as a core Customer Characteristics (CU) risk driver; Jones (1994) found it the single largest cause of overruns.
A12: 8 | B12: Schedule_Pressure_Index | C12: PR | D12: Pressman (2014) Ch.28, derived w/ COCOMO II | E12: Dimensionless ratio (>1 = risk) | F12: Ratio of COCOMO II required duration (TDEV=3.67xPM^0.28) to the calendar time actually allocated. | G12: SPI = TDEV / Actual_Duration_Given. SPI>1 means less time was allocated than COCOMO II estimates as achievable. | H12: Pressman (2014, Ch.28) lists an arbitrary completion date as a key Process (PR) risk indicator; DeMarco & Lister (1999) document rising failure rates above SPI~1.5.
A13: 9 | B13: Team_Size | C13: ST | D13: Pressman (2014) Ch.28 | E13: Count (integer, 3-15) | F13: Number of developers assigned to the project. | G13: Headcount at measurement point, excluding managers/QA unless they write code. | H13: Brooks (1995): coordination overhead grows as n(n-1)/2, so team size interacts with Staff (ST) risk beyond the optimal 5-9 range.
A14: 10 | B14: Defect_Count | C14: PS / Quality | D14: NASA / PROMISE | E14: Count (integer, >=0) | F14: Total software defects detected during testing and review. | G14: Count unique defect-tracker tickets (e.g. Bugzilla, Jira) at the measurement point. | H14: Grounded in NASA CM1/JM1/KC1/PC1 (Menzies et al., 2012); high defect counts signal quality risk, a component of Pressman's Product Size/Quality driver.
A15: 11 | B15: Defect_Density | C15: PS / Quality | D15: NASA / PROMISE | E15: Defects per KLOC | F15: Defect_Count / KSLOC. | G15: Computed at the measurement point. NASA CM1 dataset averages ~6.1 defects/KLOC; Jones (2012) baseline 5-15/KLOC pre-test, >25 = quality crisis. | H15: The primary metric driving this research's Quality risk category (RE_Quality) — see Risk_Assessment_Rules.
A16: 12 | B16: Defect_Resolution_Rate | C16: PR | D16: NASA-derived | E16: Percentage (0-100%) | F16: (Resolved_Defects / Total_Defects) x 100. | G16: Closed/resolved tickets divided by total tickets x 100, measured at a project milestone. | H16: A low resolution rate signals process breakdown / quality-backlog accumulation, part of Pressman's Process (PR) risk-monitoring guidance; retained as a monitoring/RMMM indicator.
... A18: 14 | B18: Risk_Level / Risk_Label | C18: TARGET | D18: This research (proposed) | E18: Risk_Level: ordinal 1/2/3 Risk_Label: Low/Medium/High | F18: TARGET VARIABLE. Derived from the Overall_Project_Risk_Score (weighted sum of six Pressman-style RE=PxI values) using percentile thresholds (P33.33, P66.67) computed across all 1500 projects. | G18: See Risk_Calculation_Engine and Risk_Label_Methodology for the full derivation chain and exact threshold values. | H18: The label is grounded in project metrics via documented rules end-to-end, so an ML model trained on the 12 raw features learns theoretically justified relationships rather than arbitrary correlations.

Sheet Risk_Assessment_Rules
A1: RISK ASSESSMENT RULES — Documented Probability & Impact Assignment for Every Risk Category
A2: Every Probability and Impact value calculated in 'Risk_Calculation_Engine' is generated by the rules documented below. No value is randomly assigned. Rules are band-based (deterministic functions of measurable project metrics), consistent with Pressman's (2014, Ch.28) recommendation to estimate probability from 'historical project information, expert judgement, and current project conditions' rather than fixed literature percentages. IMPORTANT — Pressman's own risk-table slides (Software Engineering: A Practitioner's Approach, Ch.28) use a DESCENDING impact scale: 1=Catastrophic, 2=Critical, 3=Marginal, 4=Negligible. This research deliberately INVERTS that scale to 1=Negligible ... 4=Catastrophic (ASCENDING) so that higher Impact numerically means higher severity, which is required for RE = P x I and the weighted aggregation to behave monotonically (higher score = higher risk). This inversion is a disclosed methodological adaptation, not a misquotation of Pressman.
A4: Risk | B4: Pressman Category | C4: Metric Used | D4: Probability Assignment Rule (band -> P value) | E4: Impact Assignment Rule (band -> I value, 1=Negligible...4=Catastrophic) | F4: Literature Source
A5: Product Size Risk | B5: PS | C5: KSLOC (COCOMO II size driver) | D5: KSLOC < 25 -> P=0.30 | 25-74.9 -> P=0.50 | 75-119.9 -> P=0.65 | >=120 -> P=0.80. Larger systems have non-linear growth in integration complexity and estimation error (Brooks, 1995; Boehm, 2000 — PM = 2.94 x KSLOC^1.10 in COCOMO II shows super-linear effort growth). | E5: Same KSLOC bands -> I=1 (<25) | I=2 (25-74.9) | I=3 (75-119.9) | I=4 (>=120). A very large system (>=120 KSLOC, the top of this dataset's COCOMO81-consistent range 1.1-149.8) that overruns its estimate has catastrophic schedule/cost consequences. | F5: Pressman (2014) Ch.28 PS category + COCOMO II (Boehm 2000)
A6: Technology Risk | B6: TE | C6: CPLX (COCOMO II Product Complexity, ordinal 1=VL...5=VH) | D6: CPLX=1(VL) -> P=0.30 | 2(L) -> P=0.40 | 3(N) -> P=0.50 | 4(H) -> P=0.65 | 5(VH) -> P=0.80. Higher complexity (control flow, computational, device-dependent, data management, UI operations per Boehm 2000 Table A.8) increases the probability of implementation difficulty and defect injection. | E6: CPLX<=2 -> I=1 | =3 -> I=2 | =4 -> I=3 | =5 -> I=4. Very High complexity (embedded/AI-class software, EAF=1.34) that goes wrong has catastrophic implementation impact; Very Low/Low complexity failures are comparatively negligible. | F6: COCOMO II (Boehm 2000, Appendix A, Table A.8)
A7: Customer Risk | B7: CU | C7: Requirements_Change_Count (approved change requests) | D7: 0-3 CRs -> P=0.25 | 4-6 -> P=0.45 | 7-9 -> P=0.65 | >=10 -> P=0.85. Jones (1994) identifies requirement volatility as the single largest cause of software project overruns; more approved CRs -> higher likelihood of continued scope instability. | E7: 0-3 -> I=1 | 4-6 -> I=2 | 7-9 -> I=3 | >=10 -> I=4. Extensive requirement volatility (>=10 CRs) causes major scope creep, re-estimation, and re-design and is treated as catastrophic; a handful of CRs is negligible. | F7: Pressman (2014) Ch.28 CU category; Jones (1994)
A8: Process Risk | B8: PR | C8: Schedule_Pressure_Index (COCOMO II TDEV / allocated duration) | D8: SPI<1.0 -> P=0.20 | 1.0-1.29 -> P=0.45 | 1.3-1.79 -> P=0.70 | >=1.8 -> P=0.90. SPI>1 means less calendar time was allocated than COCOMO II's TDEV=3.67xPM^0.28 estimates as achievable; DeMarco & Lister (Peopleware, 1999) document rising failure correlation as schedule compression increases. | E8: SPI<1.0 -> I=1 | 1.0-1.29 -> I=2 | 1.3-1.79 -> I=3 | >=1.8 -> I=4. Severe schedule compression (SPI>=1.8, i.e. the project was given ~55% or less of the COCOMO II-estimated time) threatens successful delivery and is treated as catastrophic. | F8: Pressman (2014) Ch.28 PR category; COCOMO II TDEV (Boehm 2000); DeMarco & Lister (1999)
A9: Staff Risk | B9: ST | C9: Capability_Index (composite COCOMO II ACAP/PCAP, ordinal 1=Low 2=Medium 3=High) | D9: Capability=1(Low) -> P=0.75 | =2(Medium) -> P=0.45 | =3(High) -> P=0.20. Inverse relationship: Brooks (1995) and Boehm's ACAP/PCAP cost-driver theory both show lower analyst/programmer capability increases defect injection and rework probability. | E9: Low -> I=3 | Medium -> I=2 | High -> I=1. Low personnel capability (15th-percentile ACAP/PCAP, EAF=1.369) substantially increases development risk; High-capability teams (75th percentile, EAF=0.748) contain damage even when problems occur, so residual impact is treated as low, not catastrophic. | F9: COCOMO II ACAP/PCAP (Boehm 2000, Appendix A); Brooks (1995)
A10: Quality Risk | B10: QL (NASA-derived, supplements Pressman's 5 categories per project instructions) | C10: Defect_Density (defects per KLOC) | D10: Density<5 -> P=0.20 | 5-9.9 -> P=0.45 | 10-17.9 -> P=0.70 | >=18 -> P=0.90. Jones (2012, Applied Software Measurement) documents 5-15 defects/KLOC pre-test as typical industry baseline; the NASA CM1 (PROMISE) dataset averages ~6.1 defects/KLOC. | E10: Density<5 -> I=1 | 5-9.9 -> I=2 | 10-17.9 -> I=3 | >=18 -> I=4. Jones (2012) treats >25 defects/KLOC as a 'quality crisis'; densities at or above 18/KLOC are treated as catastrophic to product quality, consistent with that literature threshold. | F10: NASA/PROMISE (Menzies et al., 2012); Jones (2012)
A12: Traceability: every Probability/Impact cell in 'Risk_Calculation_Engine' columns B-S is an IF() formula that implements exactly the band rule documented in this table for that risk — open any cell to see the live rule.

Sheet Risk_Calculation_Engine
A1: RISK CALCULATION ENGINE — Per-Project Probability, Impact, Risk Exposure (RE = P x I), Aggregation, Percentile Labeling
A2: Pressman (2014, Ch.28) defines Risk Exposure for an INDIVIDUAL risk as RE = Probability x Impact. He does NOT define a formula for combining multiple RE values into one project-level score. Column T (Overall_Project_Risk_Score) is therefore this research's PROPOSED aggregation method, not a Pressman formula. All Probability/Impact assignment rules are documented, literature-grounded, and rule-based (never random) — see 'Risk_Assessment_Rules' for the full rationale of every threshold used below.
A4: Project_ID | B4: Prob_ProductSize | C4: Impact_ProductSize | D4: RE_ProductSize | E4: Prob_Technology | F4: Impact_Technology | G4: RE_Technology | H4: Prob_Customer | I4: Impact_Customer | J4: RE_Customer | K4: Prob_Process | L4: Impact_Process | M4: RE_Process | N4: Prob_Staff | O4: Impact_Staff | P4: RE_Staff | Q4: Prob_Quality | R4: Impact_Quality | S4: RE_Quality | T4: Overall_Project_Risk_Score | U4: Risk_Label | X4: AGGREGATION WEIGHTS (proposed, sum = 1.00)
A5: =Dataset!A5 -> 1 | B5: =IF(Dataset!B5<25,0.3,IF(Dataset!B5<75,0.5,IF(Dataset!B5<120,0.65,0.8))) -> 0.65 | C5: =IF(Dataset!B5<25,1,IF(Dataset!B5<75,2,IF(Dataset!B5<120,3,4))) -> 3 | D5: =B5*C5 -> 1.95 | E5: =IF(Dataset!C5<=1,0.3,IF(Dataset!C5=2,0.4,IF(Dataset!C5=3,0.5,IF(Dataset!C5=4,0.65,0.8)))) -> 0.65 | F5: =IF(Dataset!C5<=2,1,IF(Dataset!C5=3,2,IF(Dataset!C5=4,3,4))) -> 3 | G5: =E5*F5 -> 1.95 | H5: =IF(Dataset!G5<=3,0.25,IF(Dataset!G5<=6,0.45,IF(Dataset!G5<=9,0.65,0.85))) -> 0.45 | I5: =IF(Dataset!G5<=3,1,IF(Dataset!G5<=6,2,IF(Dataset!G5<=9,3,4))) -> 2 | J5: =H5*I5 -> 0.9 | K5: =IF(Dataset!H5<1,0.2,IF(Dataset!H5<1.3,0.45,IF(Dataset!H5<1.8,0.7,0.9))) -> 0.9 | L5: =IF(Dataset!H5<1,1,IF(Dataset!H5<1.3,2,IF(Dataset!H5<1.8,3,4))) -> 4 | M5: =K5*L5 -> 3.6 | N5: =IF(Dataset!F5=1,0.75,IF(Dataset!F5=2,0.45,0.2)) -> 0.2 | O5: =IF(Dataset!F5=1,3,IF(Dataset!F5=2,2,1)) -> 1 | P5: =N5*O5 -> 0.2 | Q5: =IF(Dataset!K5<5,0.2,IF(Dataset!K5<10,0.45,IF(Dataset!K5<18,0.7,0.9))) -> 0.7 | R5: =IF(Dataset!K5<5,1,IF(Dataset!K5<10,2,IF(Dataset!K5<18,3,4))) -> 3 | S5: =Q5*R5 -> 2.1 | T5: =$Y$6*D5+$Y$7*G5+$Y$8*J5+$Y$9*M5+$Y$10*P5+$Y$11*S5 -> 1.982 | U5: =IF(T5<=$Y$15,"Low",IF(T5<=$Y$16,"Medium","High")) -> High | X5: Category | Y5: Weight
A6: =Dataset!A6 -> 2 | B6: =IF(Dataset!B6<25,0.3,IF(Dataset!B6<75,0.5,IF(Dataset!B6<120,0.65,0.8))) -> 0.65 | C6: =IF(Dataset!B6<25,1,IF(Dataset!B6<75,2,IF(Dataset!B6<120,3,4))) -> 3 | D6: =B6*C6 -> 1.95 | E6: =IF(Dataset!C6<=1,0.3,IF(Dataset!C6=2,0.4,IF(Dataset!C6=3,0.5,IF(Dataset!C6=4,0.65,0.8)))) -> 0.4 | F6: =IF(Dataset!C6<=2,1,IF(Dataset!C6=3,2,IF(Dataset!C6=4,3,4))) -> 1 | G6: =E6*F6 -> 0.4 | H6: =IF(Dataset!G6<=3,0.25,IF(Dataset!G6<=6,0.45,IF(Dataset!G6<=9,0.65,0.85))) -> 0.45 | I6: =IF(Dataset!G6<=3,1,IF(Dataset!G6<=6,2,IF(Dataset!G6<=9,3,4))) -> 2 | J6: =H6*I6 -> 0.9 | K6: =IF(Dataset!H6<1,0.2,IF(Dataset!H6<1.3,0.45,IF(Dataset!H6<1.8,0.7,0.9))) -> 0.9 | L6: =IF(Dataset!H6<1,1,IF(Dataset!H6<1.3,2,IF(Dataset!H6<1.8,3,4))) -> 4 | M6: =K6*L6 -> 3.6 | N6: =IF(Dataset!F6=1,0.75,IF(Dataset!F6=2,0.45,0.2)) -> 0.45 | O6: =IF(Dataset!F6=1,3,IF(Dataset!F6=2,2,1)) -> 2 | P6: =N6*O6 -> 0.9 | Q6: =IF(Dataset!K6<5,0.2,IF(Dataset!K6<10,0.45,IF(Dataset!K6<18,0.7,0.9))) -> 0.2 | R6: =IF(Dataset!K6<5,1,IF(Dataset!K6<10,2,IF(Dataset!K6<18,3,4))) -> 1 | S6: =Q6*R6 -> 0.2 | T6: =$Y$6*D6+$Y$7*G6+$Y$8*J6+$Y$9*M6+$Y$10*P6+$Y$11*S6 -> 1.569 | U6: =IF(T6<=$Y$15,"Low",IF(T6<=$Y$16,"Medium","High")) -> Medium | X6: Product Size (PS) | Y6: 0.18
A7: =Dataset!A7 -> 3 | B7: =IF(Dataset!B7<25,0.3,IF(Dataset!B7<75,0.5,IF(Dataset!B7<120,0.65,0.8))) -> 0.5 | C7: =IF(Dataset!B7<25,1,IF(Dataset!B7<75,2,IF(Dataset!B7<120,3,4))) -> 2 | D7: =B7*C7 -> 1 | E7: =IF(Dataset!C7<=1,0.3,IF(Dataset!C7=2,0.4,IF(Dataset!C7=3,0.5,IF(Dataset!C7=4,0.65,0.8)))) -> 0.65 | F7: =IF(Dataset!C7<=2,1,IF(Dataset!C7=3,2,IF(Dataset!C7=4,3,4))) -> 3 | G7: =E7*F7 -> 1.95 | H7: =IF(Dataset!G7<=3,0.25,IF(Dataset!G7<=6,0.45,IF(Dataset!G7<=9,0.65,0.85))) -> 0.25 | I7: =IF(Dataset!G7<=3,1,IF(Dataset!G7<=6,2,IF(Dataset!G7<=9,3,4))) -> 1 | J7: =H7*I7 -> 0.25 | K7: =IF(Dataset!H7<1,0.2,IF(Dataset!H7<1.3,0.45,IF(Dataset!H7<1.8,0.7,0.9))) -> 0.7 | L7: =IF(Dataset!H7<1,1,IF(Dataset!H7<1.3,2,IF(Dataset!H7<1.8,3,4))) -> 3 | M7: =K7*L7 -> 2.1 | N7: =IF(Dataset!F7=1,0.75,IF(Dataset!F7=2,0.45,0.2)) -> 0.2 | O7: =IF(Dataset!F7=1,3,IF(Dataset!F7=2,2,1)) -> 1 | P7: =N7*O7 -> 0.2 | Q7: =IF(Dataset!K7<5,0.2,IF(Dataset!K7<10,0.45,IF(Dataset!K7<18,0.7,0.9))) -> 0.7 | R7: =IF(Dataset!K7<5,1,IF(Dataset!K7<10,2,IF(Dataset!K7<18,3,4))) -> 3 | S7: =Q7*R7 -> 2.1 | T7: =$Y$6*D7+$Y$7*G7+$Y$8*J7+$Y$9*M7+$Y$10*P7+$Y$11*S7 -> 1.321 | U7: =IF(T7<=$Y$15,"Low",IF(T7<=$Y$16,"Medium","High")) -> Low | X7: Technology (TE) | Y7: 0.14
A8: =Dataset!A8 -> 4 | B8: =IF(Dataset!B8<25,0.3,IF(Dataset!B8<75,0.5,IF(Dataset!B8<120,0.65,0.8))) -> 0.5 | C8: =IF(Dataset!B8<25,1,IF(Dataset!B8<75,2,IF(Dataset!B8<120,3,4))) -> 2 | D8: =B8*C8 -> 1 | E8: =IF(Dataset!C8<=1,0.3,IF(Dataset!C8=2,0.4,IF(Dataset!C8=3,0.5,IF(Dataset!C8=4,0.65,0.8)))) -> 0.5 | F8: =IF(Dataset!C8<=2,1,IF(Dataset!C8=3,2,IF(Dataset!C8=4,3,4))) -> 2 | G8: =E8*F8 -> 1 | H8: =IF(Dataset!G8<=3,0.25,IF(Dataset!G8<=6,0.45,IF(Dataset!G8<=9,0.65,0.85))) -> 0.85 | I8: =IF(Dataset!G8<=3,1,IF(Dataset!G8<=6,2,IF(Dataset!G8<=9,3,4))) -> 4 | J8: =H8*I8 -> 3.4 | K8: =IF(Dataset!H8<1,0.2,IF(Dataset!H8<1.3,0.45,IF(Dataset!H8<1.8,0.7,0.9))) -> 0.45 | L8: =IF(Dataset!H8<1,1,IF(Dataset!H8<1.3,2,IF(Dataset!H8<1.8,3,4))) -> 2 | M8: =K8*L8 -> 0.9 | N8: =IF(Dataset!F8=1,0.75,IF(Dataset!F8=2,0.45,0.2)) -> 0.2 | O8: =IF(Dataset!F8=1,3,IF(Dataset!F8=2,2,1)) -> 1 | P8: =N8*O8 -> 0.2 | Q8: =IF(Dataset!K8<5,0.2,IF(Dataset!K8<10,0.45,IF(Dataset!K8<18,0.7,0.9))) -> 0.45 | R8: =IF(Dataset!K8<5,1,IF(Dataset!K8<10,2,IF(Dataset!K8<18,3,4))) -> 2 | S8: =Q8*R8 -> 0.9 | T8: =$Y$6*D8+$Y$7*G8+$Y$8*J8+$Y$9*M8+$Y$10*P8+$Y$11*S8 -> 1.362 | U8: =IF(T8<=$Y$15,"Low",IF(T8<=$Y$16,"Medium","High")) -> Medium | X8: Customer (CU) | Y8: 0.2
A9: =Dataset!A9 -> 5 | B9: =IF(Dataset!B9<25,0.3,IF(Dataset!B9<75,0.5,IF(Dataset!B9<120,0.65,0.8))) -> 0.65 | C9: =IF(Dataset!B9<25,1,IF(Dataset!B9<75,2,IF(Dataset!B9<120,3,4))) -> 3 | D9: =B9*C9 -> 1.95 | E9: =IF(Dataset!C9<=1,0.3,IF(Dataset!C9=2,0.4,IF(Dataset!C9=3,0.5,IF(Dataset!C9=4,0.65,0.8)))) -> 0.5 | F9: =IF(Dataset!C9<=2,1,IF(Dataset!C9=3,2,IF(Dataset!C9=4,3,4))) -> 2 | G9: =E9*F9 -> 1 | H9: =IF(Dataset!G9<=3,0.25,IF(Dataset!G9<=6,0.45,IF(Dataset!G9<=9,0.65,0.85))) -> 0.25 | I9: =IF(Dataset!G9<=3,1,IF(Dataset!G9<=6,2,IF(Dataset!G9<=9,3,4))) -> 1 | J9: =H9*I9 -> 0.25 | K9: =IF(Dataset!H9<1,0.2,IF(Dataset!H9<1.3,0.45,IF(Dataset!H9<1.8,0.7,0.9))) -> 0.2 | L9: =IF(Dataset!H9<1,1,IF(Dataset!H9<1.3,2,IF(Dataset!H9<1.8,3,4))) -> 1 | M9: =K9*L9 -> 0.2 | N9: =IF(Dataset!F9=1,0.75,IF(Dataset!F9=2,0.45,0.2)) -> 0.45 | O9: =IF(Dataset!F9=1,3,IF(Dataset!F9=2,2,1)) -> 2 | P9: =N9*O9 -> 0.9 | Q9: =IF(Dataset!K9<5,0.2,IF(Dataset!K9<10,0.45,IF(Dataset!K9<18,0.7,0.9))) -> 0.45 | R9: =IF(Dataset!K9<5,1,IF(Dataset!K9<10,2,IF(Dataset!K9<18,3,4))) -> 2 | S9: =Q9*R9 -> 0.9 | T9: =$Y$6*D9+$Y$7*G9+$Y$8*J9+$Y$9*M9+$Y$10*P9+$Y$11*S9 -> 0.805 | U9: =IF(T9<=$Y$15,"Low",IF(T9<=$Y$16,"Medium","High")) -> Low | X9: Process (PR) | Y9: 0.24
A10: =Dataset!A10 -> 6 | B10: =IF(Dataset!B10<25,0.3,IF(Dataset!B10<75,0.5,IF(Dataset!B10<120,0.65,0.8))) -> 0.5 | C10: =IF(Dataset!B10<25,1,IF(Dataset!B10<75,2,IF(Dataset!B10<120,3,4))) -> 2 | D10: =B10*C10 -> 1 | E10: =IF(Dataset!C10<=1,0.3,IF(Dataset!C10=2,0.4,IF(Dataset!C10=3,0.5,IF(Dataset!C10=4,0.65,0.8)))) -> 0.4 | F10: =IF(Dataset!C10<=2,1,IF(Dataset!C10=3,2,IF(Dataset!C10=4,3,4))) -> 1 | G10: =E10*F10 -> 0.4 | H10: =IF(Dataset!G10<=3,0.25,IF(Dataset!G10<=6,0.45,IF(Dataset!G10<=9,0.65,0.85))) -> 0.25 | I10: =IF(Dataset!G10<=3,1,IF(Dataset!G10<=6,2,IF(Dataset!G10<=9,3,4))) -> 1 | J10: =H10*I10 -> 0.25 | K10: =IF(Dataset!H10<1,0.2,IF(Dataset!H10<1.3,0.45,IF(Dataset!H10<1.8,0.7,0.9))) -> 0.2 | L10: =IF(Dataset!H10<1,1,IF(Dataset!H10<1.3,2,IF(Dataset!H10<1.8,3,4))) -> 1 | M10: =K10*L10 -> 0.2 | N10: =IF(Dataset!F10=1,0.75,IF(Dataset!F10=2,0.45,0.2)) -> 0.75 | O10: =IF(Dataset!F10=1,3,IF(Dataset!F10=2,2,1)) -> 3 | P10: =N10*O10 -> 2.25 | Q10: =IF(Dataset!K10<5,0.2,IF(Dataset!K10<10,0.45,IF(Dataset!K10<18,0.7,0.9))) -> 0.45 | R10: =IF(Dataset!K10<5,1,IF(Dataset!K10<10,2,IF(Dataset!K10<18,3,4))) -> 2 | S10: =Q10*R10 -> 0.9 | T10: =$Y$6*D10+$Y$7*G10+$Y$8*J10+$Y$9*M10+$Y$10*P10+$Y$11*S10 -> 0.685 | U10: =IF(T10<=$Y$15,"Low",IF(T10<=$Y$16,"Medium","High")) -> Low | X10: Staff (ST) | Y10: 0.1
A11: =Dataset!A11 -> 7 | B11: =IF(Dataset!B11<25,0.3,IF(Dataset!B11<75,0.5,IF(Dataset!B11<120,0.65,0.8))) -> 0.65 | C11: =IF(Dataset!B11<25,1,IF(Dataset!B11<75,2,IF(Dataset!B11<120,3,4))) -> 3 | D11: =B11*C11 -> 1.95 | E11: =IF(Dataset!C11<=1,0.3,IF(Dataset!C11=2,0.4,IF(Dataset!C11=3,0.5,IF(Dataset!C11=4,0.65,0.8)))) -> 0.5 | F11: =IF(Dataset!C11<=2,1,IF(Dataset!C11=3,2,IF(Dataset!C11=4,3,4))) -> 2 | G11: =E11*F11 -> 1 | H11: =IF(Dataset!G11<=3,0.25,IF(Dataset!G11<=6,0.45,IF(Dataset!G11<=9,0.65,0.85))) -> 0.85 | I11: =IF(Dataset!G11<=3,1,IF(Dataset!G11<=6,2,IF(Dataset!G11<=9,3,4))) -> 4 | J11: =H11*I11 -> 3.4 | K11: =IF(Dataset!H11<1,0.2,IF(Dataset!H11<1.3,0.45,IF(Dataset!H11<1.8,0.7,0.9))) -> 0.45 | L11: =IF(Dataset!H11<1,1,IF(Dataset!H11<1.3,2,IF(Dataset!H11<1.8,3,4))) -> 2 | M11: =K11*L11 -> 0.9 | N11: =IF(Dataset!F11=1,0.75,IF(Dataset!F11=2,0.45,0.2)) -> 0.2 | O11: =IF(Dataset!F11=1,3,IF(Dataset!F11=2,2,1)) -> 1 | P11: =N11*O11 -> 0.2 | Q11: =IF(Dataset!K11<5,0.2,IF(Dataset!K11<10,0.45,IF(Dataset!K11<18,0.7,0.9))) -> 0.45 | R11: =IF(Dataset!K11<5,1,IF(Dataset!K11<10,2,IF(Dataset!K11<18,3,4))) -> 2 | S11: =Q11*R11 -> 0.9 | T11: =$Y$6*D11+$Y$7*G11+$Y$8*J11+$Y$9*M11+$Y$10*P11+$Y$11*S11 -> 1.533 | U11: =IF(T11<=$Y$15,"Low",IF(T11<=$Y$16,"Medium","High")) -> Medium | X11: Quality (QL, NASA-derived) | Y11: 0.14
A12: =Dataset!A12 -> 8 | B12: =IF(Dataset!B12<25,0.3,IF(Dataset!B12<75,0.5,IF(Dataset!B12<120,0.65,0.8))) -> 0.65 | C12: =IF(Dataset!B12<25,1,IF(Dataset!B12<75,2,IF(Dataset!B12<120,3,4))) -> 3 | D12: =B12*C12 -> 1.95 | E12: =IF(Dataset!C12<=1,0.3,IF(Dataset!C12=2,0.4,IF(Dataset!C12=3,0.5,IF(Dataset!C12=4,0.65,0.8)))) -> 0.5 | F12: =IF(Dataset!C12<=2,1,IF(Dataset!C12=3,2,IF(Dataset!C12=4,3,4))) -> 2 | G12: =E12*F12 -> 1 | H12: =IF(Dataset!G12<=3,0.25,IF(Dataset!G12<=6,0.45,IF(Dataset!G12<=9,0.65,0.85))) -> 0.85 | I12: =IF(Dataset!G12<=3,1,IF(Dataset!G12<=6,2,IF(Dataset!G12<=9,3,4))) -> 4 | J12: =H12*I12 -> 3.4 | K12: =IF(Dataset!H12<1,0.2,IF(Dataset!H12<1.3,0.45,IF(Dataset!H12<1.8,0.7,0.9))) -> 0.9 | L12: =IF(Dataset!H12<1,1,IF(Dataset!H12<1.3,2,IF(Dataset!H12<1.8,3,4))) -> 4 | M12: =K12*L12 -> 3.6 | N12: =IF(Dataset!F12=1,0.75,IF(Dataset!F12=2,0.45,0.2)) -> 0.75 | O12: =IF(Dataset!F12=1,3,IF(Dataset!F12=2,2,1)) -> 3 | P12: =N12*O12 -> 2.25 | Q12: =IF(Dataset!K12<5,0.2,IF(Dataset!K12<10,0.45,IF(Dataset!K12<18,0.7,0.9))) -> 0.45 | R12: =IF(Dataset!K12<5,1,IF(Dataset!K12<10,2,IF(Dataset!K12<18,3,4))) -> 2 | S12: =Q12*R12 -> 0.9 | T12: =$Y$6*D12+$Y$7*G12+$Y$8*J12+$Y$9*M12+$Y$10*P12+$Y$11*S12 -> 2.386 | U12: =IF(T12<=$Y$15,"Low",IF(T12<=$Y$16,"Medium","High")) -> High | X12: SUM CHECK | Y12: =SUM(Y6:Y11) -> 1
A13: =Dataset!A13 -> 9 | B13: =IF(Dataset!B13<25,0.3,IF(Dataset!B13<75,0.5,IF(Dataset!B13<120,0.65,0.8))) -> 0.65 | C13: =IF(Dataset!B13<25,1,IF(Dataset!B13<75,2,IF(Dataset!B13<120,3,4))) -> 3 | D13: =B13*C13 -> 1.95 | E13: =IF(Dataset!C13<=1,0.3,IF(Dataset!C13=2,0.4,IF(Dataset!C13=3,0.5,IF(Dataset!C13=4,0.65,0.8)))) -> 0.5 | F13: =IF(Dataset!C13<=2,1,IF(Dataset!C13=3,2,IF(Dataset!C13=4,3,4))) -> 2 | G13: =E13*F13 -> 1 | H13: =IF(Dataset!G13<=3,0.25,IF(Dataset!G13<=6,0.45,IF(Dataset!G13<=9,0.65,0.85))) -> 0.45 | I13: =IF(Dataset!G13<=3,1,IF(Dataset!G13<=6,2,IF(Dataset!G13<=9,3,4))) -> 2 | J13: =H13*I13 -> 0.9 | K13: =IF(Dataset!H13<1,0.2,IF(Dataset!H13<1.3,0.45,IF(Dataset!H13<1.8,0.7,0.9))) -> 0.9 | L13: =IF(Dataset!H13<1,1,IF(Dataset!H13<1.3,2,IF(Dataset!H13<1.8,3,4))) -> 4 | M13: =K13*L13 -> 3.6 | N13: =IF(Dataset!F13=1,0.75,IF(Dataset!F13=2,0.45,0.2)) -> 0.45 | O13: =IF(Dataset!F13=1,3,IF(Dataset!F13=2,2,1)) -> 2 | P13: =N13*O13 -> 0.9 | Q13: =IF(Dataset!K13<5,0.2,IF(Dataset!K13<10,0.45,IF(Dataset!K13<18,0.7,0.9))) -> 0.45 | R13: =IF(Dataset!K13<5,1,IF(Dataset!K13<10,2,IF(Dataset!K13<18,3,4))) -> 2 | S13: =Q13*R13 -> 0.9 | T13: =$Y$6*D13+$Y$7*G13+$Y$8*J13+$Y$9*M13+$Y$10*P13+$Y$11*S13 -> 1.751 | U13: =IF(T13<=$Y$15,"Low",IF(T13<=$Y$16,"Medium","High")) -> Medium
A14: =Dataset!A14 -> 10 | B14: =IF(Dataset!B14<25,0.3,IF(Dataset!B14<75,0.5,IF(Dataset!B14<120,0.65,0.8))) -> 0.5 | C14: =IF(Dataset!B14<25,1,IF(Dataset!B14<75,2,IF(Dataset!B14<120,3,4))) -> 2 | D14: =B14*C14 -> 1 | E14: =IF(Dataset!C14<=1,0.3,IF(Dataset!C14=2,0.4,IF(Dataset!C14=3,0.5,IF(Dataset!C14=4,0.65,0.8)))) -> 0.4 | F14: =IF(Dataset!C14<=2,1,IF(Dataset!C14=3,2,IF(Dataset!C14=4,3,4))) -> 1 | G14: =E14*F14 -> 0.4 | H14: =IF(Dataset!G14<=3,0.25,IF(Dataset!G14<=6,0.45,IF(Dataset!G14<=9,0.65,0.85))) -> 0.65 | I14: =IF(Dataset!G14<=3,1,IF(Dataset!G14<=6,2,IF(Dataset!G14<=9,3,4))) -> 3 | J14: =H14*I14 -> 1.95 | K14: =IF(Dataset!H14<1,0.2,IF(Dataset!H14<1.3,0.45,IF(Dataset!H14<1.8,0.7,0.9))) -> 0.9 | L14: =IF(Dataset!H14<1,1,IF(Dataset!H14<1.3,2,IF(Dataset!H14<1.8,3,4))) -> 4 | M14: =K14*L14 -> 3.6 | N14: =IF(Dataset!F14=1,0.75,IF(Dataset!F14=2,0.45,0.2)) -> 0.45 | O14: =IF(Dataset!F14=1,3,IF(Dataset!F14=2,2,1)) -> 2 | P14: =N14*O14 -> 0.9 | Q14: =IF(Dataset!K14<5,0.2,IF(Dataset!K14<10,0.45,IF(Dataset!K14<18,0.7,0.9))) -> 0.2 | R14: =IF(Dataset!K14<5,1,IF(Dataset!K14<10,2,IF(Dataset!K14<18,3,4))) -> 1 | S14: =Q14*R14 -> 0.2 | T14: =$Y$6*D14+$Y$7*G14+$Y$8*J14+$Y$9*M14+$Y$10*P14+$Y$11*S14 -> 1.608 | U14: =IF(T14<=$Y$15,"Low",IF(T14<=$Y$16,"Medium","High")) -> Medium | X14: PERCENTILE RISK-LABEL THRESHOLDS
A15: =Dataset!A15 -> 11 | B15: =IF(Dataset!B15<25,0.3,IF(Dataset!B15<75,0.5,IF(Dataset!B15<120,0.65,0.8))) -> 0.8 | C15: =IF(Dataset!B15<25,1,IF(Dataset!B15<75,2,IF(Dataset!B15<120,3,4))) -> 4 | D15: =B15*C15 -> 3.2 | E15: =IF(Dataset!C15<=1,0.3,IF(Dataset!C15=2,0.4,IF(Dataset!C15=3,0.5,IF(Dataset!C15=4,0.65,0.8)))) -> 0.4 | F15: =IF(Dataset!C15<=2,1,IF(Dataset!C15=3,2,IF(Dataset!C15=4,3,4))) -> 1 | G15: =E15*F15 -> 0.4 | H15: =IF(Dataset!G15<=3,0.25,IF(Dataset!G15<=6,0.45,IF(Dataset!G15<=9,0.65,0.85))) -> 0.85 | I15: =IF(Dataset!G15<=3,1,IF(Dataset!G15<=6,2,IF(Dataset!G15<=9,3,4))) -> 4 | J15: =H15*I15 -> 3.4 | K15: =IF(Dataset!H15<1,0.2,IF(Dataset!H15<1.3,0.45,IF(Dataset!H15<1.8,0.7,0.9))) -> 0.7 | L15: =IF(Dataset!H15<1,1,IF(Dataset!H15<1.3,2,IF(Dataset!H15<1.8,3,4))) -> 3 | M15: =K15*L15 -> 2.1 | N15: =IF(Dataset!F15=1,0.75,IF(Dataset!F15=2,0.45,0.2)) -> 0.45 | O15: =IF(Dataset!F15=1,3,IF(Dataset!F15=2,2,1)) -> 2 | P15: =N15*O15 -> 0.9 | Q15: =IF(Dataset!K15<5,0.2,IF(Dataset!K15<10,0.45,IF(Dataset!K15<18,0.7,0.9))) -> 0.2 | R15: =IF(Dataset!K15<5,1,IF(Dataset!K15<10,2,IF(Dataset!K15<18,3,4))) -> 1 | S15: =Q15*R15 -> 0.2 | T15: =$Y$6*D15+$Y$7*G15+$Y$8*J15+$Y$9*M15+$Y$10*P15+$Y$11*S15 -> 1.934 | U15: =IF(T15<=$Y$15,"Low",IF(T15<=$Y$16,"Medium","High")) -> High | X15: P33.33 (Low/Medium cut) | Y15: =PERCENTILE(T5:T1504,1/3) -> 1.353
A16: =Dataset!A16 -> 12 | B16: =IF(Dataset!B16<25,0.3,IF(Dataset!B16<75,0.5,IF(Dataset!B16<120,0.65,0.8))) -> 0.5 | C16: =IF(Dataset!B16<25,1,IF(Dataset!B16<75,2,IF(Dataset!B16<120,3,4))) -> 2 | D16: =B16*C16 -> 1 | E16: =IF(Dataset!C16<=1,0.3,IF(Dataset!C16=2,0.4,IF(Dataset!C16=3,0.5,IF(Dataset!C16=4,0.65,0.8)))) -> 0.5 | F16: =IF(Dataset!C16<=2,1,IF(Dataset!C16=3,2,IF(Dataset!C16=4,3,4))) -> 2 | G16: =E16*F16 -> 1 | H16: =IF(Dataset!G16<=3,0.25,IF(Dataset!G16<=6,0.45,IF(Dataset!G16<=9,0.65,0.85))) -> 0.65 | I16: =IF(Dataset!G16<=3,1,IF(Dataset!G16<=6,2,IF(Dataset!G16<=9,3,4))) -> 3 | J16: =H16*I16 -> 1.95 | K16: =IF(Dataset!H16<1,0.2,IF(Dataset!H16<1.3,0.45,IF(Dataset!H16<1.8,0.7,0.9))) -> 0.9 | L16: =IF(Dataset!H16<1,1,IF(Dataset!H16<1.3,2,IF(Dataset!H16<1.8,3,4))) -> 4 | M16: =K16*L16 -> 3.6 | N16: =IF(Dataset!F16=1,0.75,IF(Dataset!F16=2,0.45,0.2)) -> 0.75 | O16: =IF(Dataset!F16=1,3,IF(Dataset!F16=2,2,1)) -> 3 | P16: =N16*O16 -> 2.25 | Q16: =IF(Dataset!K16<5,0.2,IF(Dataset!K16<10,0.45,IF(Dataset!K16<18,0.7,0.9))) -> 0.45 | R16: =IF(Dataset!K16<5,1,IF(Dataset!K16<10,2,IF(Dataset!K16<18,3,4))) -> 2 | S16: =Q16*R16 -> 0.9 | T16: =$Y$6*D16+$Y$7*G16+$Y$8*J16+$Y$9*M16+$Y$10*P16+$Y$11*S16 -> 1.925 | U16: =IF(T16<=$Y$15,"Low",IF(T16<=$Y$16,"Medium","High")) -> High | X16: P66.67 (Medium/High cut) | Y16: =PERCENTILE(T5:T1504,2/3) -> 1.7553333
A17: =Dataset!A17 -> 13 | B17: =IF(Dataset!B17<25,0.3,IF(Dataset!B17<75,0.5,IF(Dataset!B17<120,0.65,0.8))) -> 0.65 | C17: =IF(Dataset!B17<25,1,IF(Dataset!B17<75,2,IF(Dataset!B17<120,3,4))) -> 3 | D17: =B17*C17 -> 1.95 | E17: =IF(Dataset!C17<=1,0.3,IF(Dataset!C17=2,0.4,IF(Dataset!C17=3,0.5,IF(Dataset!C17=4,0.65,0.8)))) -> 0.4 | F17: =IF(Dataset!C17<=2,1,IF(Dataset!C17=3,2,IF(Dataset!C17=4,3,4))) -> 1 | G17: =E17*F17 -> 0.4 | H17: =IF(Dataset!G17<=3,0.25,IF(Dataset!G17<=6,0.45,IF(Dataset!G17<=9,0.65,0.85))) -> 0.45 | I17: =IF(Dataset!G17<=3,1,IF(Dataset!G17<=6,2,IF(Dataset!G17<=9,3,4))) -> 2 | J17: =H17*I17 -> 0.9 | K17: =IF(Dataset!H17<1,0.2,IF(Dataset!H17<1.3,0.45,IF(Dataset!H17<1.8,0.7,0.9))) -> 0.7 | L17: =IF(Dataset!H17<1,1,IF(Dataset!H17<1.3,2,IF(Dataset!H17<1.8,3,4))) -> 3 | M17: =K17*L17 -> 2.1 | N17: =IF(Dataset!F17=1,0.75,IF(Dataset!F17=2,0.45,0.2)) -> 0.45 | O17: =IF(Dataset!F17=1,3,IF(Dataset!F17=2,2,1)) -> 2 | P17: =N17*O17 -> 0.9 | Q17: =IF(Dataset!K17<5,0.2,IF(Dataset!K17<10,0.45,IF(Dataset!K17<18,0.7,0.9))) -> 0.2 | R17: =IF(Dataset!K17<5,1,IF(Dataset!K17<10,2,IF(Dataset!K17<18,3,4))) -> 1 | S17: =Q17*R17 -> 0.2 | T17: =$Y$6*D17+$Y$7*G17+$Y$8*J17+$Y$9*M17+$Y$10*P17+$Y$11*S17 -> 1.209 | U17: =IF(T17<=$Y$15,"Low",IF(T17<=$Y$16,"Medium","High")) -> Low
A18: =Dataset!A18 -> 14 | B18: =IF(Dataset!B18<25,0.3,IF(Dataset!B18<75,0.5,IF(Dataset!B18<120,0.65,0.8))) -> 0.65 | C18: =IF(Dataset!B18<25,1,IF(Dataset!B18<75,2,IF(Dataset!B18<120,3,4))) -> 3 | D18: =B18*C18 -> 1.95 | E18: =IF(Dataset!C18<=1,0.3,IF(Dataset!C18=2,0.4,IF(Dataset!C18=3,0.5,IF(Dataset!C18=4,0.65,0.8)))) -> 0.65 | F18: =IF(Dataset!C18<=2,1,IF(Dataset!C18=3,2,IF(Dataset!C18=4,3,4))) -> 3 | G18: =E18*F18 -> 1.95 | H18: =IF(Dataset!G18<=3,0.25,IF(Dataset!G18<=6,0.45,IF(Dataset!G18<=9,0.65,0.85))) -> 0.65 | I18: =IF(Dataset!G18<=3,1,IF(Dataset!G18<=6,2,IF(Dataset!G18<=9,3,4))) -> 3 | J18: =H18*I18 -> 1.95 | K18: =IF(Dataset!H18<1,0.2,IF(Dataset!H18<1.3,0.45,IF(Dataset!H18<1.8,0.7,0.9))) -> 0.7 | L18: =IF(Dataset!H18<1,1,IF(Dataset!H18<1.3,2,IF(Dataset!H18<1.8,3,4))) -> 3 | M18: =K18*L18 -> 2.1 | N18: =IF(Dataset!F18=1,0.75,IF(Dataset!F18=2,0.45,0.2)) -> 0.75 | O18: =IF(Dataset!F18=1,3,IF(Dataset!F18=2,2,1)) -> 3 | P18: =N18*O18 -> 2.25 | Q18: =IF(Dataset!K18<5,0.2,IF(Dataset!K18<10,0.45,IF(Dataset!K18<18,0.7,0.9))) -> 0.7 | R18: =IF(Dataset!K18<5,1,IF(Dataset!K18<10,2,IF(Dataset!K18<18,3,4))) -> 3 | S18: =Q18*R18 -> 2.1 | T18: =$Y$6*D18+$Y$7*G18+$Y$8*J18+$Y$9*M18+$Y$10*P18+$Y$11*S18 -> 2.037 | U18: =IF(T18<=$Y$15,"Low",IF(T18<=$Y$16,"Medium","High")) -> High | X18: Label counts (should be ~500/500/500 - balanced tertiles)
A19: =Dataset!A19 -> 15 | B19: =IF(Dataset!B19<25,0.3,IF(Dataset!B19<75,0.5,IF(Dataset!B19<120,0.65,0.8))) -> 0.5 | C19: =IF(Dataset!B19<25,1,IF(Dataset!B19<75,2,IF(Dataset!B19<120,3,4))) -> 2 | D19: =B19*C19 -> 1 | E19: =IF(Dataset!C19<=1,0.3,IF(Dataset!C19=2,0.4,IF(Dataset!C19=3,0.5,IF(Dataset!C19=4,0.65,0.8)))) -> 0.8 | F19: =IF(Dataset!C19<=2,1,IF(Dataset!C19=3,2,IF(Dataset!C19=4,3,4))) -> 4 | G19: =E19*F19 -> 3.2 | H19: =IF(Dataset!G19<=3,0.25,IF(Dataset!G19<=6,0.45,IF(Dataset!G19<=9,0.65,0.85))) -> 0.45 | I19: =IF(Dataset!G19<=3,1,IF(Dataset!G19<=6,2,IF(Dataset!G19<=9,3,4))) -> 2 | J19: =H19*I19 -> 0.9 | K19: =IF(Dataset!H19<1,0.2,IF(Dataset!H19<1.3,0.45,IF(Dataset!H19<1.8,0.7,0.9))) -> 0.9 | L19: =IF(Dataset!H19<1,1,IF(Dataset!H19<1.3,2,IF(Dataset!H19<1.8,3,4))) -> 4 | M19: =K19*L19 -> 3.6 | N19: =IF(Dataset!F19=1,0.75,IF(Dataset!F19=2,0.45,0.2)) -> 0.2 | O19: =IF(Dataset!F19=1,3,IF(Dataset!F19=2,2,1)) -> 1 | P19: =N19*O19 -> 0.2 | Q19: =IF(Dataset!K19<5,0.2,IF(Dataset!K19<10,0.45,IF(Dataset!K19<18,0.7,0.9))) -> 0.7 | R19: =IF(Dataset!K19<5,1,IF(Dataset!K19<10,2,IF(Dataset!K19<18,3,4))) -> 3 | S19: =Q19*R19 -> 2.1 | T19: =$Y$6*D19+$Y$7*G19+$Y$8*J19+$Y$9*M19+$Y$10*P19+$Y$11*S19 -> 1.986 | U19: =IF(T19<=$Y$15,"Low",IF(T19<=$Y$16,"Medium","High")) -> High | X19: Low | Y19: =COUNTIF(U5:U1504,"Low") -> 501
A20: =Dataset!A20 -> 16 | B20: =IF(Dataset!B20<25,0.3,IF(Dataset!B20<75,0.5,IF(Dataset!B20<120,0.65,0.8))) -> 0.65 | C20: =IF(Dataset!B20<25,1,IF(Dataset!B20<75,2,IF(Dataset!B20<120,3,4))) -> 3 | D20: =B20*C20 -> 1.95 | E20: =IF(Dataset!C20<=1,0.3,IF(Dataset!C20=2,0.4,IF(Dataset!C20=3,0.5,IF(Dataset!C20=4,0.65,0.8)))) -> 0.5 | F20: =IF(Dataset!C20<=2,1,IF(Dataset!C20=3,2,IF(Dataset!C20=4,3,4))) -> 2 | G20: =E20*F20 -> 1 | H20: =IF(Dataset!G20<=3,0.25,IF(Dataset!G20<=6,0.45,IF(Dataset!G20<=9,0.65,0.85))) -> 0.65 | I20: =IF(Dataset!G20<=3,1,IF(Dataset!G20<=6,2,IF(Dataset!G20<=9,3,4))) -> 3 | J20: =H20*I20 -> 1.95 | K20: =IF(Dataset!H20<1,0.2,IF(Dataset!H20<1.3,0.45,IF(Dataset!H20<1.8,0.7,0.9))) -> 0.7 | L20: =IF(Dataset!H20<1,1,IF(Dataset!H20<1.3,2,IF(Dataset!H20<1.8,3,4))) -> 3 | M20: =K20*L20 -> 2.1 | N20: =IF(Dataset!F20=1,0.75,IF(Dataset!F20=2,0.45,0.2)) -> 0.75 | O20: =IF(Dataset!F20=1,3,IF(Dataset!F20=2,2,1)) -> 3 | P20: =N20*O20 -> 2.25 | Q20: =IF(Dataset!K20<5,0.2,IF(Dataset!K20<10,0.45,IF(Dataset!K20<18,0.7,0.9))) -> 0.2 | R20: =IF(Dataset!K20<5,1,IF(Dataset!K20<10,2,IF(Dataset!K20<18,3,4))) -> 1 | S20: =Q20*R20 -> 0.2 | T20: =$Y$6*D20+$Y$7*G20+$Y$8*J20+$Y$9*M20+$Y$10*P20+$Y$11*S20 -> 1.638 | U20: =IF(T20<=$Y$15,"Low",IF(T20<=$Y$16,"Medium","High")) -> Medium | X20: Medium | Y20: =COUNTIF(U5:U1504,"Medium") -> 499
A21: =Dataset!A21 -> 17 | B21: =IF(Dataset!B21<25,0.3,IF(Dataset!B21<75,0.5,IF(Dataset!B21<120,0.65,0.8))) -> 0.5 | C21: =IF(Dataset!B21<25,1,IF(Dataset!B21<75,2,IF(Dataset!B21<120,3,4))) -> 2 | D21: =B21*C21 -> 1 | E21: =IF(Dataset!C21<=1,0.3,IF(Dataset!C21=2,0.4,IF(Dataset!C21=3,0.5,IF(Dataset!C21=4,0.65,0.8)))) -> 0.8 | F21: =IF(Dataset!C21<=2,1,IF(Dataset!C21=3,2,IF(Dataset!C21=4,3,4))) -> 4 | G21: =E21*F21 -> 3.2 | H21: =IF(Dataset!G21<=3,0.25,IF(Dataset!G21<=6,0.45,IF(Dataset!G21<=9,0.65,0.85))) -> 0.25 | I21: =IF(Dataset!G21<=3,1,IF(Dataset!G21<=6,2,IF(Dataset!G21<=9,3,4))) -> 1 | J21: =H21*I21 -> 0.25 | K21: =IF(Dataset!H21<1,0.2,IF(Dataset!H21<1.3,0.45,IF(Dataset!H21<1.8,0.7,0.9))) -> 0.9 | L21: =IF(Dataset!H21<1,1,IF(Dataset!H21<1.3,2,IF(Dataset!H21<1.8,3,4))) -> 4 | M21: =K21*L21 -> 3.6 | N21: =IF(Dataset!F21=1,0.75,IF(Dataset!F21=2,0.45,0.2)) -> 0.45 | O21: =IF(Dataset!F21=1,3,IF(Dataset!F21=2,2,1)) -> 2 | P21: =N21*O21 -> 0.9 | Q21: =IF(Dataset!K21<5,0.2,IF(Dataset!K21<10,0.45,IF(Dataset!K21<18,0.7,0.9))) -> 0.7 | R21: =IF(Dataset!K21<5,1,IF(Dataset!K21<10,2,IF(Dataset!K21<18,3,4))) -> 3 | S21: =Q21*R21 -> 2.1 | T21: =$Y$6*D21+$Y$7*G21+$Y$8*J21+$Y$9*M21+$Y$10*P21+$Y$11*S21 -> 1.926 | U21: =IF(T21<=$Y$15,"Low",IF(T21<=$Y$16,"Medium","High")) -> High | X21: High | Y21: =COUNTIF(U5:U1504,"High") -> 500
A22: =Dataset!A22 -> 18 | B22: =IF(Dataset!B22<25,0.3,IF(Dataset!B22<75,0.5,IF(Dataset!B22<120,0.65,0.8))) -> 0.5 | C22: =IF(Dataset!B22<25,1,IF(Dataset!B22<75,2,IF(Dataset!B22<120,3,4))) -> 2 | D22: =B22*C22 -> 1 | E22: =IF(Dataset!C22<=1,0.3,IF(Dataset!C22=2,0.4,IF(Dataset!C22=3,0.5,IF(Dataset!C22=4,0.65,0.8)))) -> 0.4 | F22: =IF(Dataset!C22<=2,1,IF(Dataset!C22=3,2,IF(Dataset!C22=4,3,4))) -> 1 | G22: =E22*F22 -> 0.4 | H22: =IF(Dataset!G22<=3,0.25,IF(Dataset!G22<=6,0.45,IF(Dataset!G22<=9,0.65,0.85))) -> 0.65 | I22: =IF(Dataset!G22<=3,1,IF(Dataset!G22<=6,2,IF(Dataset!G22<=9,3,4))) -> 3 | J22: =H22*I22 -> 1.95 | K22: =IF(Dataset!H22<1,0.2,IF(Dataset!H22<1.3,0.45,IF(Dataset!H22<1.8,0.7,0.9))) -> 0.9 | L22: =IF(Dataset!H22<1,1,IF(Dataset!H22<1.3,2,IF(Dataset!H22<1.8,3,4))) -> 4 | M22: =K22*L22 -> 3.6 | N22: =IF(Dataset!F22=1,0.75,IF(Dataset!F22=2,0.45,0.2)) -> 0.2 | O22: =IF(Dataset!F22=1,3,IF(Dataset!F22=2,2,1)) -> 1 | P22: =N22*O22 -> 0.2 | Q22: =IF(Dataset!K22<5,0.2,IF(Dataset!K22<10,0.45,IF(Dataset!K22<18,0.7,0.9))) -> 0.2 | R22: =IF(Dataset!K22<5,1,IF(Dataset!K22<10,2,IF(Dataset!K22<18,3,4))) -> 1 | S22: =Q22*R22 -> 0.2 | T22: =$Y$6*D22+$Y$7*G22+$Y$8*J22+$Y$9*M22+$Y$10*P22+$Y$11*S22 -> 1.538 | U22: =IF(T22<=$Y$15,"Low",IF(T22<=$Y$16,"Medium","High")) -> Medium
A23: =Dataset!A23 -> 19 | B23: =IF(Dataset!B23<25,0.3,IF(Dataset!B23<75,0.5,IF(Dataset!B23<120,0.65,0.8))) -> 0.65 | C23: =IF(Dataset!B23<25,1,IF(Dataset!B23<75,2,IF(Dataset!B23<120,3,4))) -> 3 | D23: =B23*C23 -> 1.95 | E23: =IF(Dataset!C23<=1,0.3,IF(Dataset!C23=2,0.4,IF(Dataset!C23=3,0.5,IF(Dataset!C23=4,0.65,0.8)))) -> 0.3 | F23: =IF(Dataset!C23<=2,1,IF(Dataset!C23=3,2,IF(Dataset!C23=4,3,4))) -> 1 | G23: =E23*F23 -> 0.3 | H23: =IF(Dataset!G23<=3,0.25,IF(Dataset!G23<=6,0.45,IF(Dataset!G23<=9,0.65,0.85))) -> 0.65 | I23: =IF(Dataset!G23<=3,1,IF(Dataset!G23<=6,2,IF(Dataset!G23<=9,3,4))) -> 3 | J23: =H23*I23 -> 1.95 | K23: =IF(Dataset!H23<1,0.2,IF(Dataset!H23<1.3,0.45,IF(Dataset!H23<1.8,0.7,0.9))) -> 0.9 | L23: =IF(Dataset!H23<1,1,IF(Dataset!H23<1.3,2,IF(Dataset!H23<1.8,3,4))) -> 4 | M23: =K23*L23 -> 3.6 | N23: =IF(Dataset!F23=1,0.75,IF(Dataset!F23=2,0.45,0.2)) -> 0.75 | O23: =IF(Dataset!F23=1,3,IF(Dataset!F23=2,2,1)) -> 3 | P23: =N23*O23 -> 2.25 | Q23: =IF(Dataset!K23<5,0.2,IF(Dataset!K23<10,0.45,IF(Dataset!K23<18,0.7,0.9))) -> 0.2 | R23: =IF(Dataset!K23<5,1,IF(Dataset!K23<10,2,IF(Dataset!K23<18,3,4))) -> 1 | S23: =Q23*R23 -> 0.2 | T23: =$Y$6*D23+$Y$7*G23+$Y$8*J23+$Y$9*M23+$Y$10*P23+$Y$11*S23 -> 1.9 | U23: =IF(T23<=$Y$15,"Low",IF(T23<=$Y$16,"Medium","High")) -> High
A24: =Dataset!A24 -> 20 | B24: =IF(Dataset!B24<25,0.3,IF(Dataset!B24<75,0.5,IF(Dataset!B24<120,0.65,0.8))) -> 0.3 | C24: =IF(Dataset!B24<25,1,IF(Dataset!B24<75,2,IF(Dataset!B24<120,3,4))) -> 1 | D24: =B24*C24 -> 0.3 | E24: =IF(Dataset!C24<=1,0.3,IF(Dataset!C24=2,0.4,IF(Dataset!C24=3,0.5,IF(Dataset!C24=4,0.65,0.8)))) -> 0.65 | F24: =IF(Dataset!C24<=2,1,IF(Dataset!C24=3,2,IF(Dataset!C24=4,3,4))) -> 3 | G24: =E24*F24 -> 1.95 | H24: =IF(Dataset!G24<=3,0.25,IF(Dataset!G24<=6,0.45,IF(Dataset!G24<=9,0.65,0.85))) -> 0.25 | I24: =IF(Dataset!G24<=3,1,IF(Dataset!G24<=6,2,IF(Dataset!G24<=9,3,4))) -> 1 | J24: =H24*I24 -> 0.25 | K24: =IF(Dataset!H24<1,0.2,IF(Dataset!H24<1.3,0.45,IF(Dataset!H24<1.8,0.7,0.9))) -> 0.2 | L24: =IF(Dataset!H24<1,1,IF(Dataset!H24<1.3,2,IF(Dataset!H24<1.8,3,4))) -> 1 | M24: =K24*L24 -> 0.2 | N24: =IF(Dataset!F24=1,0.75,IF(Dataset!F24=2,0.45,0.2)) -> 0.75 | O24: =IF(Dataset!F24=1,3,IF(Dataset!F24=2,2,1)) -> 3 | P24: =N24*O24 -> 2.25 | Q24: =IF(Dataset!K24<5,0.2,IF(Dataset!K24<10,0.45,IF(Dataset!K24<18,0.7,0.9))) -> 0.45 | R24: =IF(Dataset!K24<5,1,IF(Dataset!K24<10,2,IF(Dataset!K24<18,3,4))) -> 2 | S24: =Q24*R24 -> 0.9 | T24: =$Y$6*D24+$Y$7*G24+$Y$8*J24+$Y$9*M24+$Y$10*P24+$Y$11*S24 -> 0.776 | U24: =IF(T24<=$Y$15,"Low",IF(T24<=$Y$16,"Medium","High")) -> Low
A25: =Dataset!A25 -> 21 | B25: =IF(Dataset!B25<25,0.3,IF(Dataset!B25<75,0.5,IF(Dataset!B25<120,0.65,0.8))) -> 0.5 | C25: =IF(Dataset!B25<25,1,IF(Dataset!B25<75,2,IF(Dataset!B25<120,3,4))) -> 2 | D25: =B25*C25 -> 1 | E25: =IF(Dataset!C25<=1,0.3,IF(Dataset!C25=2,0.4,IF(Dataset!C25=3,0.5,IF(Dataset!C25=4,0.65,0.8)))) -> 0.65 | F25: =IF(Dataset!C25<=2,1,IF(Dataset!C25=3,2,IF(Dataset!C25=4,3,4))) -> 3 | G25: =E25*F25 -> 1.95 | H25: =IF(Dataset!G25<=3,0.25,IF(Dataset!G25<=6,0.45,IF(Dataset!G25<=9,0.65,0.85))) -> 0.45 | I25: =IF(Dataset!G25<=3,1,IF(Dataset!G25<=6,2,IF(Dataset!G25<=9,3,4))) -> 2 | J25: =H25*I25 -> 0.9 | K25: =IF(Dataset!H25<1,0.2,IF(Dataset!H25<1.3,0.45,IF(Dataset!H25<1.8,0.7,0.9))) -> 0.9 | L25: =IF(Dataset!H25<1,1,IF(Dataset!H25<1.3,2,IF(Dataset!H25<1.8,3,4))) -> 4 | M25: =K25*L25 -> 3.6 | N25: =IF(Dataset!F25=1,0.75,IF(Dataset!F25=2,0.45,0.2)) -> 0.2 | O25: =IF(Dataset!F25=1,3,IF(Dataset!F25=2,2,1)) -> 1 | P25: =N25*O25 -> 0.2 | Q25: =IF(Dataset!K25<5,0.2,IF(Dataset!K25<10,0.45,IF(Dataset!K25<18,0.7,0.9))) -> 0.45 | R25: =IF(Dataset!K25<5,1,IF(Dataset!K25<10,2,IF(Dataset!K25<18,3,4))) -> 2 | S25: =Q25*R25 -> 0.9 | T25: =$Y$6*D25+$Y$7*G25+$Y$8*J25+$Y$9*M25+$Y$10*P25+$Y$11*S25 -> 1.643 | U25: =IF(T25<=$Y$15,"Low",IF(T25<=$Y$16,"Medium","High")) -> Medium
A26: =Dataset!A26 -> 22 | B26: =IF(Dataset!B26<25,0.3,IF(Dataset!B26<75,0.5,IF(Dataset!B26<120,0.65,0.8))) -> 0.5 | C26: =IF(Dataset!B26<25,1,IF(Dataset!B26<75,2,IF(Dataset!B26<120,3,4))) -> 2 | D26: =B26*C26 -> 1 | E26: =IF(Dataset!C26<=1,0.3,IF(Dataset!C26=2,0.4,IF(Dataset!C26=3,0.5,IF(Dataset!C26=4,0.65,0.8)))) -> 0.65 | F26: =IF(Dataset!C26<=2,1,IF(Dataset!C26=3,2,IF(Dataset!C26=4,3,4))) -> 3 | G26: =E26*F26 -> 1.95 | H26: =IF(Dataset!G26<=3,0.25,IF(Dataset!G26<=6,0.45,IF(Dataset!G26<=9,0.65,0.85))) -> 0.45 | I26: =IF(Dataset!G26<=3,1,IF(Dataset!G26<=6,2,IF(Dataset!G26<=9,3,4))) -> 2 | J26: =H26*I26 -> 0.9 | K26: =IF(Dataset!H26<1,0.2,IF(Dataset!H26<1.3,0.45,IF(Dataset!H26<1.8,0.7,0.9))) -> 0.7 | L26: =IF(Dataset!H26<1,1,IF(Dataset!H26<1.3,2,IF(Dataset!H26<1.8,3,4))) -> 3 | M26: =K26*L26 -> 2.1 | N26: =IF(Dataset!F26=1,0.75,IF(Dataset!F26=2,0.45,0.2)) -> 0.75 | O26: =IF(Dataset!F26=1,3,IF(Dataset!F26=2,2,1)) -> 3 | P26: =N26*O26 -> 2.25 | Q26: =IF(Dataset!K26<5,0.2,IF(Dataset!K26<10,0.45,IF(Dataset!K26<18,0.7,0.9))) -> 0.45 | R26: =IF(Dataset!K26<5,1,IF(Dataset!K26<10,2,IF(Dataset!K26<18,3,4))) -> 2 | S26: =Q26*R26 -> 0.9 | T26: =$Y$6*D26+$Y$7*G26+$Y$8*J26+$Y$9*M26+$Y$10*P26+$Y$11*S26 -> 1.488 | U26: =IF(T26<=$Y$15,"Low",IF(T26<=$Y$16,"Medium","High")) -> Medium
A27: =Dataset!A27 -> 23 | B27: =IF(Dataset!B27<25,0.3,IF(Dataset!B27<75,0.5,IF(Dataset!B27<120,0.65,0.8))) -> 0.65 | C27: =IF(Dataset!B27<25,1,IF(Dataset!B27<75,2,IF(Dataset!B27<120,3,4))) -> 3 | D27: =B27*C27 -> 1.95 | E27: =IF(Dataset!C27<=1,0.3,IF(Dataset!C27=2,0.4,IF(Dataset!C27=3,0.5,IF(Dataset!C27=4,0.65,0.8)))) -> 0.3 | F27: =IF(Dataset!C27<=2,1,IF(Dataset!C27=3,2,IF(Dataset!C27=4,3,4))) -> 1 | G27: =E27*F27 -> 0.3 | H27: =IF(Dataset!G27<=3,0.25,IF(Dataset!G27<=6,0.45,IF(Dataset!G27<=9,0.65,0.85))) -> 0.45 | I27: =IF(Dataset!G27<=3,1,IF(Dataset!G27<=6,2,IF(Dataset!G27<=9,3,4))) -> 2 | J27: =H27*I27 -> 0.9 | K27: =IF(Dataset!H27<1,0.2,IF(Dataset!H27<1.3,0.45,IF(Dataset!H27<1.8,0.7,0.9))) -> 0.9 | L27: =IF(Dataset!H27<1,1,IF(Dataset!H27<1.3,2,IF(Dataset!H27<1.8,3,4))) -> 4 | M27: =K27*L27 -> 3.6 | N27: =IF(Dataset!F27=1,0.75,IF(Dataset!F27=2,0.45,0.2)) -> 0.75 | O27: =IF(Dataset!F27=1,3,IF(Dataset!F27=2,2,1)) -> 3 | P27: =N27*O27 -> 2.25 | Q27: =IF(Dataset!K27<5,0.2,IF(Dataset!K27<10,0.45,IF(Dataset!K27<18,0.7,0.9))) -> 0.2 | R27: =IF(Dataset!K27<5,1,IF(Dataset!K27<10,2,IF(Dataset!K27<18,3,4))) -> 1 | S27: =Q27*R27 -> 0.2 | T27: =$Y$6*D27+$Y$7*G27+$Y$8*J27+$Y$9*M27+$Y$10*P27+$Y$11*S27 -> 1.69 | U27: =IF(T27<=$Y$15,"Low",IF(T27<=$Y$16,"Medium","High")) -> Medium
A28: =Dataset!A28 -> 24 | B28: =IF(Dataset!B28<25,0.3,IF(Dataset!B28<75,0.5,IF(Dataset!B28<120,0.65,0.8))) -> 0.65 | C28: =IF(Dataset!B28<25,1,IF(Dataset!B28<75,2,IF(Dataset!B28<120,3,4))) -> 3 | D28: =B28*C28 -> 1.95 | E28: =IF(Dataset!C28<=1,0.3,IF(Dataset!C28=2,0.4,IF(Dataset!C28=3,0.5,IF(Dataset!C28=4,0.65,0.8)))) -> 0.65 | F28: =IF(Dataset!C28<=2,1,IF(Dataset!C28=3,2,IF(Dataset!C28=4,3,4))) -> 3 | G28: =E28*F28 -> 1.95 | H28: =IF(Dataset!G28<=3,0.25,IF(Dataset!G28<=6,0.45,IF(Dataset!G28<=9,0.65,0.85))) -> 0.25 | I28: =IF(Dataset!G28<=3,1,IF(Dataset!G28<=6,2,IF(Dataset!G28<=9,3,4))) -> 1 | J28: =H28*I28 -> 0.25 | K28: =IF(Dataset!H28<1,0.2,IF(Dataset!H28<1.3,0.45,IF(Dataset!H28<1.8,0.7,0.9))) -> 0.9 | L28: =IF(Dataset!H28<1,1,IF(Dataset!H28<1.3,2,IF(Dataset!H28<1.8,3,4))) -> 4 | M28: =K28*L28 -> 3.6 | N28: =IF(Dataset!F28=1,0.75,IF(Dataset!F28=2,0.45,0.2)) -> 0.45 | O28: =IF(Dataset!F28=1,3,IF(Dataset!F28=2,2,1)) -> 2 | P28: =N28*O28 -> 0.9 | Q28: =IF(Dataset!K28<5,0.2,IF(Dataset!K28<10,0.45,IF(Dataset!K28<18,0.7,0.9))) -> 0.7 | R28: =IF(Dataset!K28<5,1,IF(Dataset!K28<10,2,IF(Dataset!K28<18,3,4))) -> 3 | S28: =Q28*R28 -> 2.1 | T28: =$Y$6*D28+$Y$7*G28+$Y$8*J28+$Y$9*M28+$Y$10*P28+$Y$11*S28 -> 1.922 | U28: =IF(T28<=$Y$15,"Low",IF(T28<=$Y$16,"Medium","High")) -> High
A29: =Dataset!A29 -> 25 | B29: =IF(Dataset!B29<25,0.3,IF(Dataset!B29<75,0.5,IF(Dataset!B29<120,0.65,0.8))) -> 0.65 | C29: =IF(Dataset!B29<25,1,IF(Dataset!B29<75,2,IF(Dataset!B29<120,3,4))) -> 3 | D29: =B29*C29 -> 1.95 | E29: =IF(Dataset!C29<=1,0.3,IF(Dataset!C29=2,0.4,IF(Dataset!C29=3,0.5,IF(Dataset!C29=4,0.65,0.8)))) -> 0.5 | F29: =IF(Dataset!C29<=2,1,IF(Dataset!C29=3,2,IF(Dataset!C29=4,3,4))) -> 2 | G29: =E29*F29 -> 1 | H29: =IF(Dataset!G29<=3,0.25,IF(Dataset!G29<=6,0.45,IF(Dataset!G29<=9,0.65,0.85))) -> 0.65 | I29: =IF(Dataset!G29<=3,1,IF(Dataset!G29<=6,2,IF(Dataset!G29<=9,3,4))) -> 3 | J29: =H29*I29 -> 1.95 | K29: =IF(Dataset!H29<1,0.2,IF(Dataset!H29<1.3,0.45,IF(Dataset!H29<1.8,0.7,0.9))) -> 0.45 | L29: =IF(Dataset!H29<1,1,IF(Dataset!H29<1.3,2,IF(Dataset!H29<1.8,3,4))) -> 2 | M29: =K29*L29 -> 0.9 | N29: =IF(Dataset!F29=1,0.75,IF(Dataset!F29=2,0.45,0.2)) -> 0.2 | O29: =IF(Dataset!F29=1,3,IF(Dataset!F29=2,2,1)) -> 1 | P29: =N29*O29 -> 0.2 | Q29: =IF(Dataset!K29<5,0.2,IF(Dataset!K29<10,0.45,IF(Dataset!K29<18,0.7,0.9))) -> 0.2 | R29: =IF(Dataset!K29<5,1,IF(Dataset!K29<10,2,IF(Dataset!K29<18,3,4))) -> 1 | S29: =Q29*R29 -> 0.2 | T29: =$Y$6*D29+$Y$7*G29+$Y$8*J29+$Y$9*M29+$Y$10*P29+$Y$11*S29 -> 1.145 | U29: =IF(T29<=$Y$15,"Low",IF(T29<=$Y$16,"Medium","High")) -> Low
A30: =Dataset!A30 -> 26 | B30: =IF(Dataset!B30<25,0.3,IF(Dataset!B30<75,0.5,IF(Dataset!B30<120,0.65,0.8))) -> 0.3 | C30: =IF(Dataset!B30<25,1,IF(Dataset!B30<75,2,IF(Dataset!B30<120,3,4))) -> 1 | D30: =B30*C30 -> 0.3 | E30: =IF(Dataset!C30<=1,0.3,IF(Dataset!C30=2,0.4,IF(Dataset!C30=3,0.5,IF(Dataset!C30=4,0.65,0.8)))) -> 0.5 | F30: =IF(Dataset!C30<=2,1,IF(Dataset!C30=3,2,IF(Dataset!C30=4,3,4))) -> 2 | G30: =E30*F30 -> 1 | H30: =IF(Dataset!G30<=3,0.25,IF(Dataset!G30<=6,0.45,IF(Dataset!G30<=9,0.65,0.85))) -> 0.65 | I30: =IF(Dataset!G30<=3,1,IF(Dataset!G30<=6,2,IF(Dataset!G30<=9,3,4))) -> 3 | J30: =H30*I30 -> 1.95 | K30: =IF(Dataset!H30<1,0.2,IF(Dataset!H30<1.3,0.45,IF(Dataset!H30<1.8,0.7,0.9))) -> 0.9 | L30: =IF(Dataset!H30<1,1,IF(Dataset!H30<1.3,2,IF(Dataset!H30<1.8,3,4))) -> 4 | M30: =K30*L30 -> 3.6 | N30: =IF(Dataset!F30=1,0.75,IF(Dataset!F30=2,0.45,0.2)) -> 0.45 | O30: =IF(Dataset!F30=1,3,IF(Dataset!F30=2,2,1)) -> 2 | P30: =N30*O30 -> 0.9 | Q30: =IF(Dataset!K30<5,0.2,IF(Dataset!K30<10,0.45,IF(Dataset!K30<18,0.7,0.9))) -> 0.45 | R30: =IF(Dataset!K30<5,1,IF(Dataset!K30<10,2,IF(Dataset!K30<18,3,4))) -> 2 | S30: =Q30*R30 -> 0.9 | T30: =$Y$6*D30+$Y$7*G30+$Y$8*J30+$Y$9*M30+$Y$10*P30+$Y$11*S30 -> 1.664 | U30: =IF(T30<=$Y$15,"Low",IF(T30<=$Y$16,"Medium","High")) -> Medium
A31: =Dataset!A31 -> 27 | B31: =IF(Dataset!B31<25,0.3,IF(Dataset!B31<75,0.5,IF(Dataset!B31<120,0.65,0.8))) -> 0.5 | C31: =IF(Dataset!B31<25,1,IF(Dataset!B31<75,2,IF(Dataset!B31<120,3,4))) -> 2 | D31: =B31*C31 -> 1 | E31: =IF(Dataset!C31<=1,0.3,IF(Dataset!C31=2,0.4,IF(Dataset!C31=3,0.5,IF(Dataset!C31=4,0.65,0.8)))) -> 0.4 | F31: =IF(Dataset!C31<=2,1,IF(Dataset!C31=3,2,IF(Dataset!C31=4,3,4))) -> 1 | G31: =E31*F31 -> 0.4 | H31: =IF(Dataset!G31<=3,0.25,IF(Dataset!G31<=6,0.45,IF(Dataset!G31<=9,0.65,0.85))) -> 0.45 | I31: =IF(Dataset!G31<=3,1,IF(Dataset!G31<=6,2,IF(Dataset!G31<=9,3,4))) -> 2 | J31: =H31*I31 -> 0.9 | K31: =IF(Dataset!H31<1,0.2,IF(Dataset!H31<1.3,0.45,IF(Dataset!H31<1.8,0.7,0.9))) -> 0.9 | L31: =IF(Dataset!H31<1,1,IF(Dataset!H31<1.3,2,IF(Dataset!H31<1.8,3,4))) -> 4 | M31: =K31*L31 -> 3.6 | N31: =IF(Dataset!F31=1,0.75,IF(Dataset!F31=2,0.45,0.2)) -> 0.45 | O31: =IF(Dataset!F31=1,3,IF(Dataset!F31=2,2,1)) -> 2 | P31: =N31*O31 -> 0.9 | Q31: =IF(Dataset!K31<5,0.2,IF(Dataset!K31<10,0.45,IF(Dataset!K31<18,0.7,0.9))) -> 0.2 | R31: =IF(Dataset!K31<5,1,IF(Dataset!K31<10,2,IF(Dataset!K31<18,3,4))) -> 1 | S31: =Q31*R31 -> 0.2 | T31: =$Y$6*D31+$Y$7*G31+$Y$8*J31+$Y$9*M31+$Y$10*P31+$Y$11*S31 -> 1.398 | U31: =IF(T31<=$Y$15,"Low",IF(T31<=$Y$16,"Medium","High")) -> Medium
A32: =Dataset!A32 -> 28 | B32: =IF(Dataset!B32<25,0.3,IF(Dataset!B32<75,0.5,IF(Dataset!B32<120,0.65,0.8))) -> 0.5 | C32: =IF(Dataset!B32<25,1,IF(Dataset!B32<75,2,IF(Dataset!B32<120,3,4))) -> 2 | D32: =B32*C32 -> 1 | E32: =IF(Dataset!C32<=1,0.3,IF(Dataset!C32=2,0.4,IF(Dataset!C32=3,0.5,IF(Dataset!C32=4,0.65,0.8)))) -> 0.8 | F32: =IF(Dataset!C32<=2,1,IF(Dataset!C32=3,2,IF(Dataset!C32=4,3,4))) -> 4 | G32: =E32*F32 -> 3.2 | H32: =IF(Dataset!G32<=3,0.25,IF(Dataset!G32<=6,0.45,IF(Dataset!G32<=9,0.65,0.85))) -> 0.25 | I32: =IF(Dataset!G32<=3,1,IF(Dataset!G32<=6,2,IF(Dataset!G32<=9,3,4))) -> 1 | J32: =H32*I32 -> 0.25 | K32: =IF(Dataset!H32<1,0.2,IF(Dataset!H32<1.3,0.45,IF(Dataset!H32<1.8,0.7,0.9))) -> 0.7 | L32: =IF(Dataset!H32<1,1,IF(Dataset!H32<1.3,2,IF(Dataset!H32<1.8,3,4))) -> 3 | M32: =K32*L32 -> 2.1 | N32: =IF(Dataset!F32=1,0.75,IF(Dataset!F32=2,0.45,0.2)) -> 0.2 | O32: =IF(Dataset!F32=1,3,IF(Dataset!F32=2,2,1)) -> 1 | P32: =N32*O32 -> 0.2 | Q32: =IF(Dataset!K32<5,0.2,IF(Dataset!K32<10,0.45,IF(Dataset!K32<18,0.7,0.9))) -> 0.9 | R32: =IF(Dataset!K32<5,1,IF(Dataset!K32<10,2,IF(Dataset!K32<18,3,4))) -> 4 | S32: =Q32*R32 -> 3.6 | T32: =$Y$6*D32+$Y$7*G32+$Y$8*J32+$Y$9*M32+$Y$10*P32+$Y$11*S32 -> 1.706 | U32: =IF(T32<=$Y$15,"Low",IF(T32<=$Y$16,"Medium","High")) -> Medium
A33: =Dataset!A33 -> 29 | B33: =IF(Dataset!B33<25,0.3,IF(Dataset!B33<75,0.5,IF(Dataset!B33<120,0.65,0.8))) -> 0.5 | C33: =IF(Dataset!B33<25,1,IF(Dataset!B33<75,2,IF(Dataset!B33<120,3,4))) -> 2 | D33: =B33*C33 -> 1 | E33: =IF(Dataset!C33<=1,0.3,IF(Dataset!C33=2,0.4,IF(Dataset!C33=3,0.5,IF(Dataset!C33=4,0.65,0.8)))) -> 0.3 | F33: =IF(Dataset!C33<=2,1,IF(Dataset!C33=3,2,IF(Dataset!C33=4,3,4))) -> 1 | G33: =E33*F33 -> 0.3 | H33: =IF(Dataset!G33<=3,0.25,IF(Dataset!G33<=6,0.45,IF(Dataset!G33<=9,0.65,0.85))) -> 0.45 | I33: =IF(Dataset!G33<=3,1,IF(Dataset!G33<=6,2,IF(Dataset!G33<=9,3,4))) -> 2 | J33: =H33*I33 -> 0.9 | K33: =IF(Dataset!H33<1,0.2,IF(Dataset!H33<1.3,0.45,IF(Dataset!H33<1.8,0.7,0.9))) -> 0.45 | L33: =IF(Dataset!H33<1,1,IF(Dataset!H33<1.3,2,IF(Dataset!H33<1.8,3,4))) -> 2 | M33: =K33*L33 -> 0.9 | N33: =IF(Dataset!F33=1,0.75,IF(Dataset!F33=2,0.45,0.2)) -> 0.45 | O33: =IF(Dataset!F33=1,3,IF(Dataset!F33=2,2,1)) -> 2 | P33: =N33*O33 -> 0.9 | Q33: =IF(Dataset!K33<5,0.2,IF(Dataset!K33<10,0.45,IF(Dataset!K33<18,0.7,0.9))) -> 0.2 | R33: =IF(Dataset!K33<5,1,IF(Dataset!K33<10,2,IF(Dataset!K33<18,3,4))) -> 1 | S33: =Q33*R33 -> 0.2 | T33: =$Y$6*D33+$Y$7*G33+$Y$8*J33+$Y$9*M33+$Y$10*P33+$Y$11*S33 -> 0.736 | U33: =IF(T33<=$Y$15,"Low",IF(T33<=$Y$16,"Medium","High")) -> Low
... A1504: =Dataset!A1504 -> 1500 | B1504: =IF(Dataset!B1504<25,0.3,IF(Dataset!B1504<75,0.5,IF(Dataset!B1504<120,0.65,0.8))) -> 0.5 | C1504: =IF(Dataset!B1504<25,1,IF(Dataset!B1504<75,2,IF(Dataset!B1504<120,3,4))) -> 2 | D1504: =B1504*C1504 -> 1 | E1504: =IF(Dataset!C1504<=1,0.3,IF(Dataset!C1504=2,0.4,IF(Dataset!C1504=3,0.5,IF(Dataset!C1504=4,0.65,0.8)))) -> 0.5 | F1504: =IF(Dataset!C1504<=2,1,IF(Dataset!C1504=3,2,IF(Dataset!C1504=4,3,4))) -> 2 | G1504: =E1504*F1504 -> 1 | H1504: =IF(Dataset!G1504<=3,0.25,IF(Dataset!G1504<=6,0.45,IF(Dataset!G1504<=9,0.65,0.85))) -> 0.25 | I1504: =IF(Dataset!G1504<=3,1,IF(Dataset!G1504<=6,2,IF(Dataset!G1504<=9,3,4))) -> 1 | J1504: =H1504*I1504 -> 0.25 | K1504: =IF(Dataset!H1504<1,0.2,IF(Dataset!H1504<1.3,0.45,IF(Dataset!H1504<1.8,0.7,0.9))) -> 0.9 | L1504: =IF(Dataset!H1504<1,1,IF(Dataset!H1504<1.3,2,IF(Dataset!H1504<1.8,3,4))) -> 4 | M1504: =K1504*L1504 -> 3.6 | N1504: =IF(Dataset!F1504=1,0.75,IF(Dataset!F1504=2,0.45,0.2)) -> 0.45 | O1504: =IF(Dataset!F1504=1,3,IF(Dataset!F1504=2,2,1)) -> 2 | P1504: =N1504*O1504 -> 0.9 | Q1504: =IF(Dataset!K1504<5,0.2,IF(Dataset!K1504<10,0.45,IF(Dataset!K1504<18,0.7,0.9))) -> 0.2 | R1504: =IF(Dataset!K1504<5,1,IF(Dataset!K1504<10,2,IF(Dataset!K1504<18,3,4))) -> 1 | S1504: =Q1504*R1504 -> 0.2 | T1504: =$Y$6*D1504+$Y$7*G1504+$Y$8*J1504+$Y$9*M1504+$Y$10*P1504+$Y$11*S1504 -> 1.352 | U1504: =IF(T1504<=$Y$15,"Low",IF(T1504<=$Y$16,"Medium","High")) -> Low

Sheet Risk_Label_Methodology
A1: RISK LABEL METHODOLOGY — Full Derivation, Literature Grounding, and Research Contribution
A3: 1. PROBABILITY ESTIMATION APPROACH
A4: Roger Pressman (2014, Ch.28) recommends estimating risk probability using historical project information, expert judgement, and current project conditions — he does NOT publish fixed universal probability percentages. This research follows that recommendation directly:
A5: - Historical information is represented through COCOMO II software metrics (Boehm 2000), NASA software quality metrics (Menzies et al., 2012), and simulated software project scenarios built to match realistic COCOMO81/NASA ranges.
A6: - Current project conditions are represented through KSLOC, CPLX, Schedule_Pressure_Index, Requirements_Change_Count, Capability_Index, and Defect_Density (each project's own measured values).
A7: Probability is therefore estimated using predefined, project-specific mapping rules based on these measurable software-engineering metrics, banded into ranges consistent with existing literature thresholds (COCOMO ordinal categories, Jones' defect-density baselines, DeMarco & Lister's schedule-pressure findings). Every rule is fully documented, cell-by-cell, in 'Risk_Assessment_Rules'. No probability value in this workbook is randomly assigned.
A9: 2. IMPACT ESTIMATION APPROACH
A10: Impact is assigned using Pressman's four-level impact scale, with one disclosed adaptation. Pressman's original risk-table slides (Software Engineering: A Practitioner's Approach, Ch.28) rate impact as: 1=Catastrophic, 2=Critical, 3=Marginal, 4=Negligible (DESCENDING severity). This research uses an ASCENDING scale instead: 1=Negligible, 2=Marginal, 3=Critical, 4=Catastrophic.
A11: This is disclosed here explicitly as a methodological adaptation of this research, not presented as Pressman's original scale, for one practical reason: RE = Probability x Impact and the downstream weighted aggregation both need 'higher number = higher severity' to behave monotonically (higher score, higher risk). Using Pressman's original descending scale would make RE fall as impact worsens, which would break both the individual RE calculation and the project-level aggregation.
A12: Every Impact assignment is rule-based against the same measurable bands as Probability (see Risk_Assessment_Rules) and is never assigned as a bare number without a documented reason.
A14: 3. INDIVIDUAL RISK EXPOSURE (Pressman, 2014)
